<?xml version="1.0"?>
<!-- Mini Reach -->
<robot name="minireach" xmlns:xacro="http://www.ros.org/wiki/xacro">

  <!-- Constants -->
  <xacro:property name="M_PI" value="3.1415926535897931" />
  <xacro:property name="mass" value="1" /> <!-- arbitrary value for mass -->

  <!-- Support wheel characteristics -->
  <property name="support_wheel_radius"		value="0.061" />
  <property name="support_wheel_width"		value="0.02" />
  <property name="support_wheel_separation"	value="0.4" />

  <!-- Drive wheel characteristics -->
  <property name="drive_wheel_radius"		value="0.115" />
  <property name="drive_wheel_width"		value="0.055" />
  <property name="drive_wheel_pos_x"		value="0.478" />
  <property name="drive_wheel_pos_y"		value="0.0" />
  <property name="drive_wheel_pos_z"		value="0.054" />

  <!-- Import all Gazebo-customization elements -->
  <xacro:include filename="$(find minireach_description)/urdf/minireach.gazebo" />

  <!-- Import Rviz colors -->
  <xacro:include filename="$(find minireach_description)/materials/materials.xacro" />

  <!-- Macros -->
  <xacro:include filename="$(find minireach_description)/urdf/deg_to_rad.xacro"/>

  <!-- Assemblies -->
  <xacro:include filename="$(find minireach_description)/urdf/assemblies/stand_assembly.xacro"/>
  <xacro:include filename="$(find minireach_description)/urdf/assemblies/camera_assembly.xacro"/>
  <xacro:include filename="$(find minireach_description)/urdf/assemblies/cab_assembly.xacro"/>

  <!-- Wheels -->
  <xacro:include filename="$(find minireach_description)/urdf/wheels/support_wheels.xacro"/>
  <xacro:include filename="$(find minireach_description)/urdf/assemblies/drive_wheel_assembly.xacro"/>

  <!-- Sensors -->
  <!--
  <xacro:include filename="$(find minireach_description)/urdf/sensors/hokuyo_urg_04lx_ug01_laser.urdf.xacro"/>
  -->
  <xacro:include filename="$(find minireach_description)/urdf/sensors/sick_tim.urdf.xacro"/>

  <!-- Base -->
  <link name="base_link">
    <inertial>
      <origin xyz="0.347642 0.00437601 0.205332" rpy="0 0 0" />
      <mass value="50" />
	    <inertia ixx="1" ixy="0" ixz="0"
	       iyy="1" iyz="0" izz="1" />
    </inertial>

    <visual>
      <origin xyz="0 0 0" rpy="0 0 ${180 * deg_to_rad}" />
      <geometry>
        <mesh filename="package://minireach_description/meshes/support_arms/support_arms_high.stl" scale="0.001 0.001 0.001" />
      </geometry> <material name="black"/>
    </visual>

    <collision>
      <origin xyz="0 0 0" rpy="0 0 ${180 * deg_to_rad}" />
      <geometry>
        <mesh filename="package://minireach_description/meshes/support_arms/support_arms_collision.stl" />
      </geometry>
      <material name="orange" />
    </collision>
  </link>

  <!-- Base footprint -->
  <link name="base_footprint"/>

  <joint name="base_footprint_joint" type="fixed">
    <origin xyz="0 0 ${support_wheel_radius}" rpy="0 0 0" />
    <child link="base_link" />
    <parent link="base_footprint"/>
  </joint>

  <!-- Support wheels -->
  <xacro:support_wheels parent="base_link"/>

  <!-- Drive wheel assembly -->
  <xacro:drive_wheel_assembly parent="base_link"/>

  <!-- Reach -->
  <link name="reach_link">
    <inertial>
      <origin xyz="-0.1 0.000209854 0.0816012" rpy="0 0 0" />
      <mass value="36" />
      <inertia ixx="0.06" ixy="0" ixz="0"
	       iyy="0.06" iyz="0" izz="0.06" />
    </inertial>

    <visual>
      <origin xyz="0 0 0" rpy="0 0 0" />
      <geometry>
        <mesh filename="package://minireach_description/meshes/reach/reach_medium.stl" scale="0.001 0.001 0.001" />
      </geometry>
      <material name="black"/>
    </visual>

  </link>

  <joint name="reach_joint" type="prismatic">
    <origin xyz="0 0 0" rpy="0 0 ${180 * deg_to_rad}" />
    <child link="reach_link" />
    <parent link="base_link"/>
    <limit effort="2000.0" lower="0" upper="0.12" velocity="0.04"/>
    <dynamics damping="200"/>
  </joint>

  <!-- Stand assembly -->
  <xacro:stand_assembly parent="reach_link"/>

  <!-- Cab assembly -->
  <xacro:cab_assembly parent="base_link"/>

  <!-- Battery -->
  <link name="battery_link">
    <inertial>
      <origin xyz="0 0 0" rpy="0 0 0" />
      <mass value="20" />
	    <inertia ixx="1" ixy="0" ixz="0"
	       iyy="1" iyz="0" izz="1" />
    </inertial>

    <visual>
      <origin xyz="-0.215 0 0.19" rpy="${-90 * deg_to_rad} 0 ${90 * deg_to_rad}" />
      <geometry>
        <mesh filename="package://minireach_description/meshes/battery/battery_medium.stl" scale="0.001 0.001 0.001" />
      </geometry>
      <material name="green"/>
    </visual>

  </link>

  <joint name="battery_joint" type="fixed">
    <origin xyz="0 0 0" rpy="0 0 ${180 * deg_to_rad}" />
    <child link="battery_link" />
    <parent link="base_link"/>
  </joint>


  <!-- Camera assembly -->
  <xacro:camera_assembly parent="fork_link"/>

  <!-- Fork Laser -->
  <link name="fork_laser_holder_link">
    <inertial>
      <origin xyz="0 0 0" rpy="0 0 0" />
      <mass value="0.1" />
	    <inertia ixx="0.01" ixy="0" ixz="0"
	       iyy="0.01" iyz="0" izz="0.01" />
    </inertial>

    <visual>
      <origin xyz="0 0 0" rpy="0 0 0" />
      <geometry>
        <mesh filename="package://minireach_description/meshes/lidar_holder/fork_lidar_holder.stl" scale="0.001 0.001 0.001" />
      </geometry>
      <material name="black"/>
    </visual>
  </link>

  <joint name="fork_laser_holder_joint" type="fixed">
    <origin xyz="-0.005 0.165 0.0765" rpy="0 0 ${180 * deg_to_rad}" />
    <child link="fork_laser_holder_link" />
    <parent link="base_link"/>
  </joint>

  <xacro:sick_tim561 name="laser1" ros_topic="scan1" min_angle="${-120 * deg_to_rad}" max_angle="${100 * deg_to_rad}" />


  <joint name="laser1_mount_joint" type="fixed">
    <origin xyz="0.038 -0.038 0" rpy="0 0 0" />
    <child link="laser1_mount_link"/>
    <parent link="fork_laser_holder_link"/>
  </joint>


  <!-- Drive Wheel Laser -->
  <link name="drive_wheel_laser_holder_link">
    <inertial>
      <origin xyz="0 0 0" rpy="0 0 0" />
      <mass value="0.1" />
	    <inertia ixx="0.01" ixy="0" ixz="0"
	       iyy="0.01" iyz="0" izz="0.01" />
    </inertial>

    <visual>
      <origin xyz="0 0 0" rpy="0 0 0" />
      <geometry>
        <mesh filename="package://minireach_description/meshes/lidar_holder/drive_wheel_lidar_holder.stl" scale="0.001 0.001 0.001" />
      </geometry>
      <material name="blue"/>
    </visual>
  </link>

  <joint name="drive_wheel_laser_holder_joint" type="fixed">
    <origin xyz="0.619 0 0.205" rpy="${180 * deg_to_rad} 0 ${180 * deg_to_rad}" />
    <child link="drive_wheel_laser_holder_link" />
    <parent link="base_link"/>
  </joint>

  <xacro:sick_tim561 name="laser2" ros_topic="scan2"  min_angle="${-95 * deg_to_rad}" max_angle="${95 * deg_to_rad}"/>

  <joint name="laser2_mount_joint" type="fixed">
    <origin xyz="-0.0355 0 0" rpy="0 0 ${180 * deg_to_rad}" />
    <child link="laser2_mount_link"/>
    <parent link="drive_wheel_laser_holder_link"/>
  </joint>

  <!-- IMU -->
  <!--
  <link name="imu_link">
    <inertial>
      <mass value="0.001"/>
      <origin rpy="0 0 0" xyz="0 0 0"/>
      <inertia ixx="0.0001" ixy="0" ixz="0" iyy="0.000001" iyz="0" izz="0.0001"/>
    </inertial>
    <visual>
      <origin rpy="0 0 0" xyz="0 0 0"/>
      <geometry>
        <box size="0.001 0.001 0.001"/>
      </geometry>
    </visual>
    <collision>
      <origin rpy="0 0 0" xyz="0 0 0"/>
      <geometry>
        <box size=".001 .001 .001"/>
      </geometry>
    </collision>
  </link>

  <joint name="imu_joint" type="fixed">
    <axis xyz="1 0 0"/>
    <origin xyz="-0.5 0 0.6"/>
    <parent link="base_footprint"/>
    <child link="imu_link"/>
  </joint>
  -->


 <!-- Transmissions -->
 <transmission name="reach_tran">
   <type>transmission_interface/SimpleTransmission</type>
   <joint name="reach_joint">
     <hardwareInterface>VelocityJointInterface</hardwareInterface>
   </joint>
   <actuator name="actuator1">
     <hardwareInterface>VelocityJointInterface</hardwareInterface>
     <mechanicalReduction>1</mechanicalReduction>
   </actuator>
 </transmission>


</robot>
