<?xml version="1.0"?>

<robot xmlns:xacro="http://ros.org/wiki/xacro">

  <xacro:macro name="stand_assembly" params="parent">

    <!-- Stand part -->
    <link name="stand_link">
      <visual>
        <origin xyz="-0.15 0 0.03" rpy="0 0 0"/>
        <geometry>
          <mesh filename="package://minireach_description/meshes/stand/stand_medium.stl" scale="0.001 0.001 0.001"/>
        </geometry>
        <material name="black"/>
      </visual>
    </link>

    <joint name="stand_joint" type="fixed">
      <origin xyz="0 0 0" rpy="0 0 0"/>
      <child link="stand_link"/>
      <parent link="${parent}"/>
    </joint>

    <!-- Gejd -->
    <link name="gejd_link">
      <inertial>
        <origin xyz="0.0408946 -0.0000376151 0.536784" rpy="0 0 0" />
        <mass value="12" />
        <inertia ixx="0.2" ixy="0" ixz="0"
           iyy="0.2" iyz="0" izz="0.2" />
      </inertial>

      <visual>
        <origin xyz="0 0 0.03" rpy="0 0 0" />
        <geometry>
          <mesh filename="package://minireach_description/meshes/gejd/gejd_medium.stl" scale="0.001 0.001 0.001" />
        </geometry>
        <material name="black"/>
      </visual>

      <collision>
        <origin xyz="0.05 0 0.45" rpy="0 0 0" />
        <geometry>
          <box size="0.145 0.284 1" />
        </geometry>
        <material name="black" />
      </collision>
    </link>

    <joint name="gejd_joint" type="prismatic">
      <origin xyz="-0.15 0 0" rpy="0 0 0" />
      <child link="gejd_link" />
      <parent link="${parent}"/>
      <axis xyz="0 0 1"/>
      <limit effort="1000.0" lower="0" upper="1.0" velocity="0.05"/>
      <mimic joint="fork_joint" multiplier="0.5"/>
    </joint>

    <!-- Fork -->
    <link name="fork_link">
      <inertial>
        <origin xyz="0 0 0" rpy="0 0 0" />
        <mass value="3" />
        <inertia ixx="0.01" ixy="0" ixz="0"
           iyy="0.01" iyz="0" izz="0.01" />
      </inertial>

      <visual>
        <origin xyz="0 0 0" rpy="0 ${90 * deg_to_rad} 0" />
        <geometry>
          <mesh filename="package://minireach_description/meshes/fork/fork_medium.stl" scale="0.001 0.001 0.001" />
        </geometry>
        <material name="black"/>
      </visual>

      <collision>
        <origin xyz="0.008 0 -0.15" rpy="0 ${90 * deg_to_rad} 0" />
        <geometry>
          <box size="0.4 0.15 0.005" />
        </geometry>
        <material name="black" />
      </collision>
    </link>

    <joint name="fork_joint" type="prismatic">
      <origin xyz="0 0 -0.06" rpy="0 ${-90 * deg_to_rad} 0" />
      <child link="fork_link" />
      <parent link="${parent}"/>
      <limit effort="1000.0" lower="0" upper="1.0" velocity="0.1"/>
      <dynamics damping="1000"/>
    </joint>

    <!--
    <link name="fork_sim_hook_link">
      <collision>
        <origin xyz="0.013 0 -0.39" rpy="0 ${90 * deg_to_rad} 0" />
        <geometry>
          <box size="0.01 0.15 0.013" />
        </geometry>
        <material name="black" />
      </collision>
    </link>

    <joint name="fork_sim_hook_joint" type="fixed">
      <origin xyz="0 0 0" rpy="0 0 0"/>
      <child link="fork_sim_hook_link"/>
      <parent link="fork_link"/>
    </joint>

    <gazebo reference="fork_sim_hook_link">
      <material>Gazebo/Black</material>
      <kp>1000000.0</kp>
      <kd>100.0</kd>
      <mu1>Inf</mu1>
      <mu2>Inf</mu2>
      <fdir1>1 0 0</fdir1>
      <maxVel>0.2</maxVel>
      <minDepth>0.003</minDepth>
      <implicitSpringDamper>1</implicitSpringDamper>
    </gazebo>
    -->


    <!-- Transmissions -->
    <transmission name="fork_tran">
     <type>transmission_interface/SimpleTransmission</type>
     <joint name="fork_joint">
       <hardwareInterface>PositionJointInterface</hardwareInterface>
     </joint>
     <actuator name="actuator2">
       <hardwareInterface>PositionJointInterface</hardwareInterface>
       <mechanicalReduction>1</mechanicalReduction>
     </actuator>
    </transmission>

    <!-- Gazebo extentions -->
    <gazebo reference="stand_link">
      <material>Gazebo/Black</material>
    </gazebo>

    <gazebo reference="gejd_link">
      <material>Gazebo/Black</material>
    </gazebo>

    <gazebo reference="fork_link">
      <material>Gazebo/Black</material>
      <kp>1000000.0</kp>
      <kd>100.0</kd>
      <mu1>Inf</mu1>
      <mu2>Inf</mu2>
      <fdir1>1 0 0</fdir1>
      <maxVel>0.2</maxVel>
      <minDepth>0.003</minDepth>
      <implicitSpringDamper>1</implicitSpringDamper>
    </gazebo>

  </xacro:macro>
</robot>
