<?xml version="1.0"?>

<robot xmlns:xacro="http://ros.org/wiki/xacro">

  <!--
  <xacro:include filename="$(find minireach_description)/urdf/sensors/astra.urdf.xacro"/>
  <xacro:include filename="$(find minireach_description)/urdf/sensors/kinect.urdf.xacro"/>
  -->
  <xacro:include filename="$(find minireach_description)/urdf/sensors/astra_no_stand.urdf.xacro"/>

  <xacro:macro name="camera_assembly" params="parent">


    <!-- Camera Holder -->
    <link name="camera_holder_link">
      <inertial>
        <origin xyz="0 0 0" rpy="0 0 0" />
        <mass value="1" />
        <inertia ixx="0.01" ixy="0" ixz="0"
           iyy="0.01" iyz="0" izz="0.01" />
      </inertial>

      <visual>
        <origin xyz="0 0 0" rpy="0 ${90 * deg_to_rad} 0"/>
        <geometry>
          <mesh filename="package://minireach_description/meshes/camera_holder/camera_holder_medium.stl" scale="0.001 0.001 0.001" />
        </geometry>
        <material name="grey"/>
      </visual>
    </link>

    <joint name="camera_holder_joint" type="fixed">
      <origin xyz="0 0 0" ryp="0 0 0"/>
      <child link="camera_holder_link"/>
      <parent link="${parent}"/>
    </joint>

    <!-- AX-12 Servo -->
    <link name="camera_servo_attachment_link">
      <inertial>
        <origin xyz="-0.06 0 0.892" rpy="0 ${90 * deg_to_rad} 0" />
        <mass value="0.053" />
        <inertia ixx="0" ixy="0" ixz="0"
           iyy="0" iyz="0" izz="0" />
      </inertial>

      <visual>
        <origin xyz="0.864 0 0.008" rpy="0 ${180 * deg_to_rad} ${-90 * deg_to_rad}" />
        <geometry>
          <mesh filename="package://minireach_description/meshes/servo_ax12/servo_ax12_medium.stl" scale="0.001 0.001 0.001" />
        </geometry>
        <material name="black"/>
      </visual>
    </link>

    <joint name="camera_servo_attachment_joint" type="fixed">
      <origin xyz="0 0 0" rpy="0 0 0"/>
      <child link="camera_servo_attachment_link"/>
      <parent link="camera_holder_link"/>
    </joint>


    <!-- Servo frame -->
    <link name="camera_servo_tilt_frame_link">
      <inertial>
        <origin xyz="-0.0635 0 0.8338" rpy="0 ${90 * deg_to_rad} 0" />
        <mass value="0.006" />
        <inertia ixx="0.0000254" ixy="0" ixz="0.000000001232"
           iyy="0.000009623" iyz="0" izz="0.00002258" />
      </inertial>

      <visual>
        <origin xyz="0 0 0" rpy="0 0 0"/>
        <geometry>
          <mesh filename="package://minireach_description/meshes/servo_frame/servo_frame_medium.stl" scale="0.001 0.001 0.001"/>
        </geometry>
        <material name="grey"/>
      </visual>
    </link>


    <joint name="camera_servo_tilt_frame_joint" type="revolute">
      <origin xyz="0.88 0 0.007" rpy="${90 * deg_to_rad} 0 ${90 * deg_to_rad}"/>
      <child link="camera_servo_tilt_frame_link"/>
      <parent link="camera_servo_attachment_link"/>
      <limit effort="1000.0" lower="-0.4" upper="${M_PI / 2}" velocity="0.5"/>
    </joint>

    <!-- Sensors -->

    <!-- Orbbec Astra -->
    <link name="astra_support_link"/>
    <link name="astra_link"/>

    <joint name="astra_support_joint" type="fixed">
      <child link="astra_support_link" />
      <parent link="camera_servo_tilt_frame_link"/>
      <origin xyz="0 0.005 0.032" rpy="0 0 ${-90 * deg_to_rad}"/>
    </joint>

    <joint name="astra_joint" type="fixed">
      <child link="astra_link" />
      <parent link="astra_support_link"/>
      <origin xyz="0 0 0" rpy="0 0 0"/>
    </joint>

    <xacro:sensor_astra parent="astra_link"/>

    <!-- ZED camera -->
    <!--
    <link name="zed_camera_link" type="fixed">
      <inertial>
        <origin xyz="-0.296881 0.000209854 0.0816012" rpy="0 ${90 * deg_to_rad} 0" />
        <mass value="0.159" />
        <inertia ixx="0.0003" ixy="0" ixz="0"
           iyy="0.00002038" iyz="0" izz="0.0003" />
      </inertial>

      <visual>
        <origin xyz="0 0 0" rpy="0 0 0"/>
        <geometry>
          <mesh filename="package://minireach_description/meshes/zed_camera/zed_camera_high.stl" scale="0.001 0.001 0.001"/>
        </geometry>
        <material name="grey"/>
      </visual>
    </link>

    <joint name="zed_camera_joint" type="fixed">
      <origin xyz="0 0.0165 0.04" rpy="0 0 ${-90 * deg_to_rad}"/>
      <child link="zed_camera_link"/>
      <parent link="camera_servo_tilt_frame_link"/>
    </joint>
    -->

    <!-- Kinect -->
    <!--

    <link name="kinect_support_link"/>
    <link name="kinect_link"/>

    <joint name="kinect_support_joint" type="fixed">
      <child link="kinect_support_link" />
      <parent link="camera_servo_tilt_frame_link"/>
      <origin xyz="0 0 0" rpy="0 ${90 * deg_to_rad} 0"/>
    </joint>

    <joint name="kinect_joint" type="fixed">
      <child link="kinect_link" />
      <parent link="kinect_support_link"/>
      <origin xyz="0 0 0" rpy="0 0 0"/>
    </joint>

    <xacro:sensor_kinect parent="kinect_link"/>
    -->


    <!-- Transmissions -->
   <transmission name="camera_servo_tilt_frame_tran">
     <type>transmission_interface/SimpleTransmission</type>
     <joint name="camera_servo_tilt_frame_joint">
       <hardwareInterface>PositionJointInterface</hardwareInterface>
     </joint>
     <actuator name="camera_servo_tilt">
       <hardwareInterface>PositionJointInterface</hardwareInterface>
       <mechanicalReduction>1</mechanicalReduction>
     </actuator>
   </transmission>

    <!-- Gazebo extentions -->
    <gazebo reference="camera_holder_link">
      <material>Gazebo/Grey</material>
      <mu1>10</mu1>
      <mu2>10</mu2>
    </gazebo>
    
    <gazebo reference="camera_servo_attachment_link">
      <material>Gazebo/Black</material>
      <mu1>10</mu1>
      <mu2>10</mu2>
    </gazebo>

    <gazebo reference="camera_servo_tilt_frame_link">
      <material>Gazebo/Grey</material>
      <mu1>10</mu1>
      <mu2>10</mu2>
    </gazebo>

  </xacro:macro>
</robot>

